[2024-02-28 14:28:57,548: INFO: main: welcome to project]
[2024-03-02 20:21:00,392: INFO: main: >>>>>> stage Data Ingestion stage started <<<<<<]
[2024-03-02 20:21:00,393: INFO: configuration: this is  the value config\config.yaml]
[2024-03-02 20:21:00,394: INFO: configuration: this  is path config\config.yaml]
[2024-03-02 20:21:00,395: INFO: configuration: this is the location C:\Users\abhik\Desktop\chicken-disease-mlops]
[2024-03-02 20:21:00,395: ERROR: main: 'WindowsPath' object has no attribute 'artifact_root']
Traceback (most recent call last):
  File "C:\Users\abhik\Desktop\chicken-disease-mlops\main.py", line 10, in <module>
    data_ingestion.main()
  File "C:\Users\abhik\Desktop\chicken-disease-mlops\cnnClassifier\pipeline\stage_01_data_ingestion.py", line 14, in main
    config = Configuration_manager()
  File "C:\Users\abhik\Desktop\chicken-disease-mlops\cnnClassifier\config\configuration.py", line 17, in __init__
    create_directories([self.config.artifact_root])
AttributeError: 'WindowsPath' object has no attribute 'artifact_root'
[2024-03-02 20:24:56,539: INFO: main: >>>>>> stage Data Ingestion stage started <<<<<<]
[2024-03-02 20:24:56,541: INFO: configuration: this is  the value config\config.yaml]
[2024-03-02 20:24:56,542: INFO: configuration: this  is path config\config.yaml]
[2024-03-02 20:24:56,543: INFO: configuration: this is the location C:\Users\abhik\Desktop\chicken-disease-mlops]
[2024-03-02 20:24:56,546: INFO: configuration: {'artifact_root': 'artifacts', 'data_ingestion': {'root_dir': 'artifacts/data_ingestion', 'source_url': 'https://github.com/entbappy/Branching-tutorial/blob/master/Chicken-fecal-images.zip', 'local_data_file': 'artifacts/data_ingestion/data.zip', 'unzip_dir': 'artifacts/data_ingestion'}}]
[2024-03-02 20:24:56,548: ERROR: main: 'WindowsPath' object has no attribute 'artifact_root']
Traceback (most recent call last):
  File "C:\Users\abhik\Desktop\chicken-disease-mlops\main.py", line 10, in <module>
    data_ingestion.main()
  File "C:\Users\abhik\Desktop\chicken-disease-mlops\cnnClassifier\pipeline\stage_01_data_ingestion.py", line 14, in main
    config = Configuration_manager()
  File "C:\Users\abhik\Desktop\chicken-disease-mlops\cnnClassifier\config\configuration.py", line 20, in __init__
    create_directories([self.config.artifact_root])
AttributeError: 'WindowsPath' object has no attribute 'artifact_root'
[2024-03-02 20:26:41,827: INFO: main: >>>>>> stage Data Ingestion stage started <<<<<<]
[2024-03-02 20:26:41,830: INFO: configuration: this is  the value config\config.yaml]
[2024-03-02 20:26:41,831: INFO: configuration: this  is path config\config.yaml]
[2024-03-02 20:26:41,831: INFO: configuration: this is the location C:\Users\abhik\Desktop\chicken-disease-mlops]
[2024-03-02 20:26:41,834: INFO: configuration: {'artifact_root': 'artifacts', 'data_ingestion': {'root_dir': 'artifacts/data_ingestion', 'source_url': 'https://github.com/entbappy/Branching-tutorial/blob/master/Chicken-fecal-images.zip', 'local_data_file': 'artifacts/data_ingestion/data.zip', 'unzip_dir': 'artifacts/data_ingestion'}}]
[2024-03-02 20:26:41,837: ERROR: main: 'WindowsPath' object is not subscriptable]
Traceback (most recent call last):
  File "C:\Users\abhik\Desktop\chicken-disease-mlops\main.py", line 10, in <module>
    data_ingestion.main()
  File "C:\Users\abhik\Desktop\chicken-disease-mlops\cnnClassifier\pipeline\stage_01_data_ingestion.py", line 14, in main
    config = Configuration_manager()
  File "C:\Users\abhik\Desktop\chicken-disease-mlops\cnnClassifier\config\configuration.py", line 20, in __init__
    create_directories([self.config['artifact_root']])
TypeError: 'WindowsPath' object is not subscriptable
[2024-03-02 20:30:41,021: INFO: main: >>>>>> stage Data Ingestion stage started <<<<<<]
[2024-03-02 20:30:41,025: INFO: common: yaml file: config\config.yaml loaded successfully]
[2024-03-02 20:30:41,037: INFO: common: yaml file: params.yaml loaded successfully]
[2024-03-02 20:30:41,038: ERROR: main: yaml file is empty]
Traceback (most recent call last):
  File "C:\Users\abhik\Desktop\chicken-disease-mlops\cnnClassifier\utils\common.py", line 33, in read_yaml
    return ConfigBox(content)
  File "box\box.py", line 259, in box.box.Box.__init__
box.exceptions.BoxValueError: First argument must be mapping or iterable

During handling of the above exception, another exception occurred:

Traceback (most recent call last):
  File "C:\Users\abhik\Desktop\chicken-disease-mlops\main.py", line 10, in <module>
    data_ingestion.main()
  File "C:\Users\abhik\Desktop\chicken-disease-mlops\cnnClassifier\pipeline\stage_01_data_ingestion.py", line 14, in main
    config = Configuration_manager()
  File "C:\Users\abhik\Desktop\chicken-disease-mlops\cnnClassifier\config\configuration.py", line 13, in __init__
    self.params = read_yaml(params_file_path)
  File "C:\Users\abhik\Desktop\chicken-disease-mlops\venv\lib\site-packages\ensure\main.py", line 849, in __call__
    return_val = self.f(*args, **kwargs)
  File "C:\Users\abhik\Desktop\chicken-disease-mlops\cnnClassifier\utils\common.py", line 35, in read_yaml
    raise ValueError("yaml file is empty")
ValueError: yaml file is empty
[2024-03-02 20:31:29,266: INFO: main: >>>>>> stage Data Ingestion stage started <<<<<<]
[2024-03-02 20:31:29,271: INFO: common: yaml file: config\config.yaml loaded successfully]
[2024-03-02 20:31:29,272: INFO: common: yaml file: params.yaml loaded successfully]
[2024-03-02 20:31:29,273: ERROR: main: yaml file is empty]
Traceback (most recent call last):
  File "C:\Users\abhik\Desktop\chicken-disease-mlops\cnnClassifier\utils\common.py", line 33, in read_yaml
    return ConfigBox(content)
  File "box\box.py", line 259, in box.box.Box.__init__
box.exceptions.BoxValueError: First argument must be mapping or iterable

During handling of the above exception, another exception occurred:

Traceback (most recent call last):
  File "C:\Users\abhik\Desktop\chicken-disease-mlops\main.py", line 10, in <module>
    data_ingestion.main()
  File "C:\Users\abhik\Desktop\chicken-disease-mlops\cnnClassifier\pipeline\stage_01_data_ingestion.py", line 14, in main
    config = Configuration_manager()
  File "C:\Users\abhik\Desktop\chicken-disease-mlops\cnnClassifier\config\configuration.py", line 13, in __init__
    self.params = read_yaml(params_file_path)
  File "C:\Users\abhik\Desktop\chicken-disease-mlops\venv\lib\site-packages\ensure\main.py", line 849, in __call__
    return_val = self.f(*args, **kwargs)
  File "C:\Users\abhik\Desktop\chicken-disease-mlops\cnnClassifier\utils\common.py", line 35, in read_yaml
    raise ValueError("yaml file is empty")
ValueError: yaml file is empty
[2024-03-02 20:31:59,600: INFO: main: >>>>>> stage Data Ingestion stage started <<<<<<]
[2024-03-02 20:31:59,605: INFO: common: yaml file: config\config.yaml loaded successfully]
[2024-03-02 20:31:59,606: INFO: common: yaml file: params.yaml loaded successfully]
[2024-03-02 20:31:59,607: ERROR: main: yaml file is empty]
Traceback (most recent call last):
  File "C:\Users\abhik\Desktop\chicken-disease-mlops\cnnClassifier\utils\common.py", line 33, in read_yaml
    return ConfigBox(content)
  File "box\box.py", line 259, in box.box.Box.__init__
box.exceptions.BoxValueError: First argument must be mapping or iterable

During handling of the above exception, another exception occurred:

Traceback (most recent call last):
  File "C:\Users\abhik\Desktop\chicken-disease-mlops\main.py", line 10, in <module>
    data_ingestion.main()
  File "C:\Users\abhik\Desktop\chicken-disease-mlops\cnnClassifier\pipeline\stage_01_data_ingestion.py", line 14, in main
    config = Configuration_manager()
  File "C:\Users\abhik\Desktop\chicken-disease-mlops\cnnClassifier\config\configuration.py", line 13, in __init__
    self.params = read_yaml(params_file_path)
  File "C:\Users\abhik\Desktop\chicken-disease-mlops\venv\lib\site-packages\ensure\main.py", line 849, in __call__
    return_val = self.f(*args, **kwargs)
  File "C:\Users\abhik\Desktop\chicken-disease-mlops\cnnClassifier\utils\common.py", line 35, in read_yaml
    raise ValueError("yaml file is empty")
ValueError: yaml file is empty
[2024-03-02 20:33:06,512: INFO: main: >>>>>> stage Data Ingestion stage started <<<<<<]
[2024-03-02 20:33:06,524: INFO: common: yaml file: config\config.yaml loaded successfully]
[2024-03-02 20:33:06,524: INFO: common: yaml file: params.yaml loaded successfully]
[2024-03-02 20:33:06,533: ERROR: main: yaml file is empty]
Traceback (most recent call last):
  File "C:\Users\abhik\Desktop\chicken-disease-mlops\cnnClassifier\utils\common.py", line 33, in read_yaml
    return ConfigBox(content)
  File "box\box.py", line 259, in box.box.Box.__init__
box.exceptions.BoxValueError: First argument must be mapping or iterable

During handling of the above exception, another exception occurred:

Traceback (most recent call last):
  File "C:\Users\abhik\Desktop\chicken-disease-mlops\main.py", line 10, in <module>
    data_ingestion.main()
  File "C:\Users\abhik\Desktop\chicken-disease-mlops\cnnClassifier\pipeline\stage_01_data_ingestion.py", line 14, in main
    config = Configuration_manager()
  File "C:\Users\abhik\Desktop\chicken-disease-mlops\cnnClassifier\config\configuration.py", line 13, in __init__
    self.params = read_yaml(params_file_path)
  File "C:\Users\abhik\Desktop\chicken-disease-mlops\venv\lib\site-packages\ensure\main.py", line 849, in __call__
    return_val = self.f(*args, **kwargs)
  File "C:\Users\abhik\Desktop\chicken-disease-mlops\cnnClassifier\utils\common.py", line 35, in read_yaml
    raise ValueError("yaml file is empty")
ValueError: yaml file is empty
[2024-03-02 20:37:10,686: INFO: main: >>>>>> stage Data Ingestion stage started <<<<<<]
[2024-03-02 20:37:10,692: INFO: common: yaml file: config\config.yaml loaded successfully]
[2024-03-02 20:37:10,693: INFO: common: yaml file: params.yaml loaded successfully]
[2024-03-02 20:37:10,695: ERROR: main: yaml file is empty]
Traceback (most recent call last):
  File "C:\Users\abhik\Desktop\chicken-disease-mlops\cnnClassifier\utils\common.py", line 33, in read_yaml
    return ConfigBox(content)
  File "box\box.py", line 259, in box.box.Box.__init__
box.exceptions.BoxValueError: First argument must be mapping or iterable

During handling of the above exception, another exception occurred:

Traceback (most recent call last):
  File "C:\Users\abhik\Desktop\chicken-disease-mlops\main.py", line 10, in <module>
    data_ingestion.main()
  File "C:\Users\abhik\Desktop\chicken-disease-mlops\cnnClassifier\pipeline\stage_01_data_ingestion.py", line 14, in main
    config = Configuration_manager()
  File "C:\Users\abhik\Desktop\chicken-disease-mlops\cnnClassifier\config\configuration.py", line 13, in __init__
    self.params = read_yaml(params_file_path)
  File "C:\Users\abhik\Desktop\chicken-disease-mlops\venv\lib\site-packages\ensure\main.py", line 849, in __call__
    return_val = self.f(*args, **kwargs)
  File "C:\Users\abhik\Desktop\chicken-disease-mlops\cnnClassifier\utils\common.py", line 35, in read_yaml
    raise ValueError("yaml file is empty")
ValueError: yaml file is empty
[2024-03-02 20:39:46,264: INFO: main: >>>>>> stage Data Ingestion stage started <<<<<<]
[2024-03-02 20:39:46,269: INFO: common: yaml file: config\config.yaml loaded successfully]
[2024-03-02 20:39:46,271: INFO: common: yaml file: params.yaml loaded successfully]
[2024-03-02 20:39:46,272: ERROR: main: yaml file is empty]
Traceback (most recent call last):
  File "C:\Users\abhik\Desktop\chicken-disease-mlops\cnnClassifier\utils\common.py", line 33, in read_yaml
    return dict(content)
TypeError: 'NoneType' object is not iterable

During handling of the above exception, another exception occurred:

Traceback (most recent call last):
  File "C:\Users\abhik\Desktop\chicken-disease-mlops\main.py", line 10, in <module>
    data_ingestion.main()
  File "C:\Users\abhik\Desktop\chicken-disease-mlops\cnnClassifier\pipeline\stage_01_data_ingestion.py", line 14, in main
    config = Configuration_manager()
  File "C:\Users\abhik\Desktop\chicken-disease-mlops\cnnClassifier\config\configuration.py", line 13, in __init__
    self.params = read_yaml(params_file_path)
  File "C:\Users\abhik\Desktop\chicken-disease-mlops\venv\lib\site-packages\ensure\main.py", line 849, in __call__
    return_val = self.f(*args, **kwargs)
  File "C:\Users\abhik\Desktop\chicken-disease-mlops\cnnClassifier\utils\common.py", line 35, in read_yaml
    raise ValueError("yaml file is empty")
ValueError: yaml file is empty
[2024-03-02 20:41:55,751: INFO: main: >>>>>> stage Data Ingestion stage started <<<<<<]
[2024-03-02 20:41:55,758: INFO: common: yaml file: config\config.yaml loaded successfully]
[2024-03-02 20:41:55,759: INFO: common: <class 'dict'>]
[2024-03-02 20:41:55,760: INFO: common: yaml file: params.yaml loaded successfully]
[2024-03-02 20:41:55,761: INFO: common: <class 'NoneType'>]
[2024-03-02 20:41:55,762: ERROR: main: Return value of <function read_yaml at 0x000001AF7AA3A320> of type <class 'NoneType'> does not match annotation type <class 'dict'>]
Traceback (most recent call last):
  File "C:\Users\abhik\Desktop\chicken-disease-mlops\main.py", line 10, in <module>
    data_ingestion.main()
  File "C:\Users\abhik\Desktop\chicken-disease-mlops\cnnClassifier\pipeline\stage_01_data_ingestion.py", line 14, in main
    config = Configuration_manager()
  File "C:\Users\abhik\Desktop\chicken-disease-mlops\cnnClassifier\config\configuration.py", line 13, in __init__
    self.params = read_yaml(params_file_path)
  File "C:\Users\abhik\Desktop\chicken-disease-mlops\venv\lib\site-packages\ensure\main.py", line 855, in __call__
    raise EnsureError(msg.format(
ensure.main.EnsureError: Return value of <function read_yaml at 0x000001AF7AA3A320> of type <class 'NoneType'> does not match annotation type <class 'dict'>
[2024-03-02 20:42:33,555: INFO: main: >>>>>> stage Data Ingestion stage started <<<<<<]
[2024-03-02 20:42:33,571: INFO: common: yaml file: config\config.yaml loaded successfully]
[2024-03-02 20:42:33,572: INFO: common: <class 'dict'>]
[2024-03-02 20:42:33,573: INFO: common: yaml file: params.yaml loaded successfully]
[2024-03-02 20:42:33,574: INFO: common: <class 'NoneType'>]
[2024-03-02 20:42:33,575: ERROR: main: Return value of <function read_yaml at 0x0000023A6BC7A320> of type <class 'NoneType'> does not match annotation type <class 'dict'>]
Traceback (most recent call last):
  File "C:\Users\abhik\Desktop\chicken-disease-mlops\main.py", line 10, in <module>
    data_ingestion.main()
  File "C:\Users\abhik\Desktop\chicken-disease-mlops\cnnClassifier\pipeline\stage_01_data_ingestion.py", line 14, in main
    config = Configuration_manager()
  File "C:\Users\abhik\Desktop\chicken-disease-mlops\cnnClassifier\config\configuration.py", line 13, in __init__
    self.params = read_yaml(params_file_path)
  File "C:\Users\abhik\Desktop\chicken-disease-mlops\venv\lib\site-packages\ensure\main.py", line 855, in __call__
    raise EnsureError(msg.format(
ensure.main.EnsureError: Return value of <function read_yaml at 0x0000023A6BC7A320> of type <class 'NoneType'> does not match annotation type <class 'dict'>
[2024-03-02 20:46:39,955: INFO: main: >>>>>> stage Data Ingestion stage started <<<<<<]
[2024-03-02 20:46:39,959: INFO: common: yaml file: config\config.yaml loaded successfully]
[2024-03-02 20:46:39,960: INFO: common: yaml file: params.yaml loaded successfully]
[2024-03-02 20:46:39,961: ERROR: main: Return value of <function read_yaml at 0x0000018FD727A320> of type <class 'NoneType'> does not match annotation type <class 'dict'>]
Traceback (most recent call last):
  File "C:\Users\abhik\Desktop\chicken-disease-mlops\main.py", line 10, in <module>
    data_ingestion.main()
  File "C:\Users\abhik\Desktop\chicken-disease-mlops\cnnClassifier\pipeline\stage_01_data_ingestion.py", line 14, in main
    config = Configuration_manager()
  File "C:\Users\abhik\Desktop\chicken-disease-mlops\cnnClassifier\config\configuration.py", line 13, in __init__
    self.params = read_yaml(params_file_path)
  File "C:\Users\abhik\Desktop\chicken-disease-mlops\venv\lib\site-packages\ensure\main.py", line 855, in __call__
    raise EnsureError(msg.format(
ensure.main.EnsureError: Return value of <function read_yaml at 0x0000018FD727A320> of type <class 'NoneType'> does not match annotation type <class 'dict'>
[2024-03-02 22:31:34,776: INFO: main: >>>>>> stage Data Ingestion stage started <<<<<<]
[2024-03-02 22:31:34,784: INFO: common: yaml file: config\config.yaml loaded successfully]
[2024-03-02 22:31:34,785: INFO: common: yaml file: params.yaml loaded successfully]
[2024-03-02 22:31:34,786: ERROR: main: Return value of <function read_yaml at 0x0000017C0C034DC0> of type <class 'NoneType'> does not match annotation type <class 'dict'>]
Traceback (most recent call last):
  File "c:\Users\abhik\Desktop\chicken-disease-mlops\main.py", line 10, in <module>
    data_ingestion.main()
  File "c:\Users\abhik\Desktop\chicken-disease-mlops\cnnClassifier\pipeline\stage_01_data_ingestion.py", line 14, in main
    config = Configuration_manager()
  File "c:\Users\abhik\Desktop\chicken-disease-mlops\cnnClassifier\config\configuration.py", line 13, in __init__
    self.params = read_yaml(params_file_path)
  File "C:\Users\abhik\Desktop\chicken-disease-mlops\venv\lib\site-packages\ensure\main.py", line 855, in __call__
    raise EnsureError(msg.format(
ensure.main.EnsureError: Return value of <function read_yaml at 0x0000017C0C034DC0> of type <class 'NoneType'> does not match annotation type <class 'dict'>
[2024-03-02 22:34:36,089: INFO: main: >>>>>> stage Data Ingestion stage started <<<<<<]
[2024-03-02 22:34:36,093: INFO: common: yaml file: config\config.yaml loaded successfully]
[2024-03-02 22:34:36,095: INFO: common: yaml file: params.yaml loaded successfully]
[2024-03-02 22:34:36,097: ERROR: main: Return value of <function read_yaml at 0x00000256CDEA2B90> of type <class 'NoneType'> does not match annotation type <class 'dict'>]
Traceback (most recent call last):
  File "C:\Users\abhik\Desktop\chicken-disease-mlops\main.py", line 10, in <module>
    data_ingestion.main()
  File "C:\Users\abhik\Desktop\chicken-disease-mlops\cnnClassifier\pipeline\stage_01_data_ingestion.py", line 14, in main
    config = Configuration_manager()
  File "C:\Users\abhik\Desktop\chicken-disease-mlops\cnnClassifier\config\configuration.py", line 13, in __init__
    self.params = read_yaml(params_file_path)
  File "C:\Users\abhik\Desktop\chicken-disease-mlops\venv\lib\site-packages\ensure\main.py", line 855, in __call__
    raise EnsureError(msg.format(
ensure.main.EnsureError: Return value of <function read_yaml at 0x00000256CDEA2B90> of type <class 'NoneType'> does not match annotation type <class 'dict'>
[2024-03-02 22:38:18,053: INFO: main: >>>>>> stage Data Ingestion stage started <<<<<<]
[2024-03-02 22:38:18,058: INFO: common: yaml file: config\config.yaml loaded successfully]
[2024-03-02 22:38:18,062: INFO: common: yaml file: params.yaml loaded successfully]
[2024-03-02 22:38:18,064: ERROR: main: Return value of <function read_yaml at 0x0000026C73E7A320> of type <class 'NoneType'> does not match annotation type <class 'dict'>]
Traceback (most recent call last):
  File "C:\Users\abhik\Desktop\chicken-disease-mlops\main.py", line 10, in <module>
    data_ingestion.main()
  File "C:\Users\abhik\Desktop\chicken-disease-mlops\cnnClassifier\pipeline\stage_01_data_ingestion.py", line 14, in main
    config = Configuration_manager()
  File "C:\Users\abhik\Desktop\chicken-disease-mlops\cnnClassifier\config\configuration.py", line 13, in __init__
    self.params = read_yaml(params_file_path)
  File "C:\Users\abhik\Desktop\chicken-disease-mlops\venv\lib\site-packages\ensure\main.py", line 855, in __call__
    raise EnsureError(msg.format(
ensure.main.EnsureError: Return value of <function read_yaml at 0x0000026C73E7A320> of type <class 'NoneType'> does not match annotation type <class 'dict'>
[2024-03-02 22:40:34,222: INFO: main: >>>>>> stage Data Ingestion stage started <<<<<<]
[2024-03-02 22:40:34,226: INFO: common: yaml file: config\config.yaml loaded successfully]
[2024-03-02 22:40:34,230: INFO: common: yaml file: params.yaml loaded successfully]
[2024-03-02 22:40:34,232: ERROR: main: Return value of <function read_yaml at 0x000002AC04A62C20> of type <class 'NoneType'> does not match annotation type <class 'dict'>]
Traceback (most recent call last):
  File "C:\Users\abhik\Desktop\chicken-disease-mlops\main.py", line 10, in <module>
    data_ingestion.main()
  File "C:\Users\abhik\Desktop\chicken-disease-mlops\cnnClassifier\pipeline\stage_01_data_ingestion.py", line 14, in main
    config = Configuration_manager()
  File "C:\Users\abhik\Desktop\chicken-disease-mlops\cnnClassifier\config\configuration.py", line 13, in __init__
    self.params = read_yaml(params_file_path)
  File "C:\Users\abhik\Desktop\chicken-disease-mlops\venv\lib\site-packages\ensure\main.py", line 855, in __call__
    raise EnsureError(msg.format(
ensure.main.EnsureError: Return value of <function read_yaml at 0x000002AC04A62C20> of type <class 'NoneType'> does not match annotation type <class 'dict'>
[2024-03-02 22:45:02,990: INFO: main: >>>>>> stage Data Ingestion stage started <<<<<<]
[2024-03-02 22:45:02,993: INFO: common: yaml file: config\config.yaml loaded successfully]
[2024-03-02 22:45:03,049: INFO: common: yaml file: params.yaml loaded successfully]
[2024-03-02 22:45:03,054: INFO: configuration: this is yaml {'artifacts_root': 'artifacts', 'data_ingestion': {'root_dir': 'artifacts/data_ingestion', 'source_URL': 'https://github.com/entbappy/Branching-tutorial/raw/master/Chicken-fecal-images.zip', 'local_data_file': 'artifacts/data_ingestion/data.zip', 'unzip_dir': 'artifacts/data_ingestion'}}]
[2024-03-02 22:45:03,057: ERROR: main: 'dict' object has no attribute 'data_ingestion']
Traceback (most recent call last):
  File "C:\Users\abhik\Desktop\chicken-disease-mlops\main.py", line 10, in <module>
    data_ingestion.main()
  File "C:\Users\abhik\Desktop\chicken-disease-mlops\cnnClassifier\pipeline\stage_01_data_ingestion.py", line 15, in main
    data_ingestion_config = config.get_data_ingestion_config()
  File "C:\Users\abhik\Desktop\chicken-disease-mlops\cnnClassifier\config\configuration.py", line 19, in get_data_ingestion_config
    config = self.config.data_ingestion
AttributeError: 'dict' object has no attribute 'data_ingestion'
[2024-03-02 22:46:14,948: INFO: main: >>>>>> stage Data Ingestion stage started <<<<<<]
[2024-03-02 22:46:14,954: INFO: common: yaml file: config\config.yaml loaded successfully]
[2024-03-02 22:46:14,967: INFO: common: yaml file: params.yaml loaded successfully]
[2024-03-02 22:46:14,970: INFO: common: created directory at: artifacts]
[2024-03-02 22:46:14,971: ERROR: main: local variable 'create_directories' referenced before assignment]
Traceback (most recent call last):
  File "C:\Users\abhik\Desktop\chicken-disease-mlops\main.py", line 10, in <module>
    data_ingestion.main()
  File "C:\Users\abhik\Desktop\chicken-disease-mlops\cnnClassifier\pipeline\stage_01_data_ingestion.py", line 15, in main
    data_ingestion_config = config.get_data_ingestion_config()
  File "C:\Users\abhik\Desktop\chicken-disease-mlops\cnnClassifier\config\configuration.py", line 18, in get_data_ingestion_config
    create_directories =  create_directories([config.root_dir])
UnboundLocalError: local variable 'create_directories' referenced before assignment
[2024-03-02 22:48:29,903: INFO: main: >>>>>> stage Data Ingestion stage started <<<<<<]
[2024-03-02 22:48:29,906: INFO: common: yaml file: config\config.yaml loaded successfully]
[2024-03-02 22:48:29,909: INFO: common: yaml file: params.yaml loaded successfully]
[2024-03-02 22:48:29,910: INFO: common: created directory at: artifacts]
[2024-03-02 22:48:29,912: INFO: common: created directory at: artifacts/data_ingestion]
[2024-03-02 22:48:29,918: ERROR: main: "'ConfigBox' object has no attribute 'source_url'"]
Traceback (most recent call last):
  File "box\box.py", line 503, in box.box.Box.__getitem__
KeyError: 'source_url'

The above exception was the direct cause of the following exception:

Traceback (most recent call last):
  File "box\box.py", line 536, in box.box.Box.__getattr__
  File "box\box.py", line 524, in box.box.Box.__getitem__
box.exceptions.BoxKeyError: "'source_url'"

During handling of the above exception, another exception occurred:

Traceback (most recent call last):
  File "box\box.py", line 538, in box.box.Box.__getattr__
AttributeError: 'ConfigBox' object has no attribute 'source_url'

The above exception was the direct cause of the following exception:

Traceback (most recent call last):
  File "box\config_box.py", line 28, in box.config_box.ConfigBox.__getattr__
  File "box\box.py", line 552, in box.box.Box.__getattr__
box.exceptions.BoxKeyError: "'ConfigBox' object has no attribute 'source_url'"

During handling of the above exception, another exception occurred:

Traceback (most recent call last):
  File "box\box.py", line 503, in box.box.Box.__getitem__
KeyError: 'source_url'

The above exception was the direct cause of the following exception:

Traceback (most recent call last):
  File "box\box.py", line 536, in box.box.Box.__getattr__
  File "box\box.py", line 524, in box.box.Box.__getitem__
box.exceptions.BoxKeyError: "'source_url'"

During handling of the above exception, another exception occurred:

Traceback (most recent call last):
  File "box\box.py", line 538, in box.box.Box.__getattr__
AttributeError: 'ConfigBox' object has no attribute 'source_url'

The above exception was the direct cause of the following exception:

Traceback (most recent call last):
  File "C:\Users\abhik\Desktop\chicken-disease-mlops\main.py", line 10, in <module>
    data_ingestion.main()
  File "C:\Users\abhik\Desktop\chicken-disease-mlops\cnnClassifier\pipeline\stage_01_data_ingestion.py", line 15, in main
    data_ingestion_config = config.get_data_ingestion_config()
  File "C:\Users\abhik\Desktop\chicken-disease-mlops\cnnClassifier\config\configuration.py", line 21, in get_data_ingestion_config
    source_url=config.source_url,
  File "box\config_box.py", line 30, in box.config_box.ConfigBox.__getattr__
  File "box\box.py", line 552, in box.box.Box.__getattr__
box.exceptions.BoxKeyError: "'ConfigBox' object has no attribute 'source_url'"
[2024-03-02 22:48:55,384: INFO: main: >>>>>> stage Data Ingestion stage started <<<<<<]
[2024-03-02 22:48:55,399: INFO: common: yaml file: config\config.yaml loaded successfully]
[2024-03-02 22:48:55,408: INFO: common: yaml file: params.yaml loaded successfully]
[2024-03-02 22:48:55,409: INFO: common: created directory at: artifacts]
[2024-03-02 22:48:55,411: INFO: common: created directory at: artifacts/data_ingestion]
[2024-03-02 22:48:55,412: ERROR: main: type object 'DataIngestionConfig' has no attribute 'local_file_path']
Traceback (most recent call last):
  File "C:\Users\abhik\Desktop\chicken-disease-mlops\main.py", line 10, in <module>
    data_ingestion.main()
  File "C:\Users\abhik\Desktop\chicken-disease-mlops\cnnClassifier\pipeline\stage_01_data_ingestion.py", line 17, in main
    data_ingestion.download_file()
  File "C:\Users\abhik\Desktop\chicken-disease-mlops\cnnClassifier\components\data_ingestion.py", line 15, in download_file
    if not os.path.exists(self.config.local_file_path):
AttributeError: type object 'DataIngestionConfig' has no attribute 'local_file_path'
[2024-03-02 22:49:11,530: INFO: main: >>>>>> stage Data Ingestion stage started <<<<<<]
[2024-03-02 22:49:11,544: INFO: common: yaml file: config\config.yaml loaded successfully]
[2024-03-02 22:49:11,551: INFO: common: yaml file: params.yaml loaded successfully]
[2024-03-02 22:49:11,552: INFO: common: created directory at: artifacts]
[2024-03-02 22:49:11,554: INFO: common: created directory at: artifacts/data_ingestion]
[2024-03-02 22:49:11,555: ERROR: main: "'ConfigBox' object has no attribute 'local_data_file'"]
Traceback (most recent call last):
  File "box\box.py", line 503, in box.box.Box.__getitem__
KeyError: 'local_data_file'

The above exception was the direct cause of the following exception:

Traceback (most recent call last):
  File "box\box.py", line 536, in box.box.Box.__getattr__
  File "box\box.py", line 524, in box.box.Box.__getitem__
box.exceptions.BoxKeyError: "'local_data_file'"

During handling of the above exception, another exception occurred:

Traceback (most recent call last):
  File "box\box.py", line 538, in box.box.Box.__getattr__
AttributeError: 'ConfigBox' object has no attribute 'local_data_file'

The above exception was the direct cause of the following exception:

Traceback (most recent call last):
  File "box\config_box.py", line 28, in box.config_box.ConfigBox.__getattr__
  File "box\box.py", line 552, in box.box.Box.__getattr__
box.exceptions.BoxKeyError: "'ConfigBox' object has no attribute 'local_data_file'"

During handling of the above exception, another exception occurred:

Traceback (most recent call last):
  File "box\box.py", line 503, in box.box.Box.__getitem__
KeyError: 'local_data_file'

The above exception was the direct cause of the following exception:

Traceback (most recent call last):
  File "box\box.py", line 536, in box.box.Box.__getattr__
  File "box\box.py", line 524, in box.box.Box.__getitem__
box.exceptions.BoxKeyError: "'local_data_file'"

During handling of the above exception, another exception occurred:

Traceback (most recent call last):
  File "box\box.py", line 538, in box.box.Box.__getattr__
AttributeError: 'ConfigBox' object has no attribute 'local_data_file'

The above exception was the direct cause of the following exception:

Traceback (most recent call last):
  File "C:\Users\abhik\Desktop\chicken-disease-mlops\main.py", line 10, in <module>
    data_ingestion.main()
  File "C:\Users\abhik\Desktop\chicken-disease-mlops\cnnClassifier\pipeline\stage_01_data_ingestion.py", line 15, in main
    data_ingestion_config = config.get_data_ingestion_config()
  File "C:\Users\abhik\Desktop\chicken-disease-mlops\cnnClassifier\config\configuration.py", line 22, in get_data_ingestion_config
    local_file_path=config.local_data_file,
  File "box\config_box.py", line 30, in box.config_box.ConfigBox.__getattr__
  File "box\box.py", line 552, in box.box.Box.__getattr__
box.exceptions.BoxKeyError: "'ConfigBox' object has no attribute 'local_data_file'"
[2024-03-02 22:49:37,892: INFO: main: >>>>>> stage Data Ingestion stage started <<<<<<]
[2024-03-02 22:49:37,908: INFO: common: yaml file: config\config.yaml loaded successfully]
[2024-03-02 22:49:37,911: INFO: common: yaml file: params.yaml loaded successfully]
[2024-03-02 22:49:37,911: INFO: common: created directory at: artifacts]
[2024-03-02 22:49:37,913: INFO: common: created directory at: artifacts/data_ingestion]
[2024-03-02 22:49:37,914: ERROR: main: type object 'DataIngestionConfig' has no attribute 'local_file_path']
Traceback (most recent call last):
  File "C:\Users\abhik\Desktop\chicken-disease-mlops\main.py", line 10, in <module>
    data_ingestion.main()
  File "C:\Users\abhik\Desktop\chicken-disease-mlops\cnnClassifier\pipeline\stage_01_data_ingestion.py", line 17, in main
    data_ingestion.download_file()
  File "C:\Users\abhik\Desktop\chicken-disease-mlops\cnnClassifier\components\data_ingestion.py", line 15, in download_file
    if not os.path.exists(self.config.local_file_path):
AttributeError: type object 'DataIngestionConfig' has no attribute 'local_file_path'
[2024-03-02 22:51:36,466: INFO: main: >>>>>> stage Data Ingestion stage started <<<<<<]
[2024-03-02 22:51:36,472: INFO: common: yaml file: config\config.yaml loaded successfully]
[2024-03-02 22:51:36,473: INFO: common: yaml file: params.yaml loaded successfully]
[2024-03-02 22:51:36,475: INFO: common: created directory at: artifacts]
[2024-03-02 22:51:36,476: INFO: common: created directory at: artifacts/data_ingestion]
[2024-03-02 22:51:36,478: ERROR: main: type object 'DataIngestionConfig' has no attribute 'local_file_path']
Traceback (most recent call last):
  File "C:\Users\abhik\Desktop\chicken-disease-mlops\main.py", line 10, in <module>
    data_ingestion.main()
  File "C:\Users\abhik\Desktop\chicken-disease-mlops\cnnClassifier\pipeline\stage_01_data_ingestion.py", line 17, in main
    data_ingestion.download_file()
  File "C:\Users\abhik\Desktop\chicken-disease-mlops\cnnClassifier\components\data_ingestion.py", line 16, in download_file
    if not os.path.exists(self.config.local_file_path):
AttributeError: type object 'DataIngestionConfig' has no attribute 'local_file_path'
[2024-03-02 22:52:19,809: INFO: main: >>>>>> stage Data Ingestion stage started <<<<<<]
[2024-03-02 22:52:19,813: INFO: common: yaml file: config\config.yaml loaded successfully]
[2024-03-02 22:52:19,814: INFO: common: yaml file: params.yaml loaded successfully]
[2024-03-02 22:52:19,815: INFO: common: created directory at: artifacts]
[2024-03-02 22:52:19,817: INFO: common: created directory at: artifacts/data_ingestion]
[2024-03-02 22:52:19,817: ERROR: main: type object 'DataIngestionConfig' has no attribute 'local_file_path']
Traceback (most recent call last):
  File "C:\Users\abhik\Desktop\chicken-disease-mlops\main.py", line 10, in <module>
    data_ingestion.main()
  File "C:\Users\abhik\Desktop\chicken-disease-mlops\cnnClassifier\pipeline\stage_01_data_ingestion.py", line 17, in main
    data_ingestion.download_file()
  File "C:\Users\abhik\Desktop\chicken-disease-mlops\cnnClassifier\components\data_ingestion.py", line 16, in download_file
    if not os.path.exists(self.config.local_file_path):
AttributeError: type object 'DataIngestionConfig' has no attribute 'local_file_path'
[2024-03-02 22:53:46,579: INFO: main: >>>>>> stage Data Ingestion stage started <<<<<<]
[2024-03-02 22:53:46,585: INFO: common: yaml file: config\config.yaml loaded successfully]
[2024-03-02 22:53:46,588: INFO: common: yaml file: params.yaml loaded successfully]
[2024-03-02 22:53:46,589: INFO: common: created directory at: artifacts]
[2024-03-02 22:53:46,591: INFO: common: created directory at: artifacts/data_ingestion]
[2024-03-02 22:53:46,591: ERROR: main: type object 'DataIngestionConfig' has no attribute 'local_file_path']
Traceback (most recent call last):
  File "C:\Users\abhik\Desktop\chicken-disease-mlops\main.py", line 10, in <module>
    data_ingestion.main()
  File "C:\Users\abhik\Desktop\chicken-disease-mlops\cnnClassifier\pipeline\stage_01_data_ingestion.py", line 17, in main
    data_ingestion.download_file()
  File "C:\Users\abhik\Desktop\chicken-disease-mlops\cnnClassifier\components\data_ingestion.py", line 16, in download_file
    if not os.path.exists(self.config.local_file_path):
AttributeError: type object 'DataIngestionConfig' has no attribute 'local_file_path'
[2024-03-02 22:55:02,184: INFO: main: >>>>>> stage Data Ingestion stage started <<<<<<]
[2024-03-02 22:55:02,193: INFO: common: yaml file: config\config.yaml loaded successfully]
[2024-03-02 22:55:02,196: INFO: common: yaml file: params.yaml loaded successfully]
[2024-03-02 22:55:02,197: INFO: common: created directory at: artifacts]
[2024-03-02 22:55:02,198: INFO: common: created directory at: artifacts/data_ingestion]
[2024-03-02 22:55:02,200: ERROR: main: DataIngestionConfig.__init__() missing 4 required positional arguments: 'root_dir', 'source_url', 'local_file_path', and 'unzip_dir']
Traceback (most recent call last):
  File "C:\Users\abhik\Desktop\chicken-disease-mlops\main.py", line 10, in <module>
    data_ingestion.main()
  File "C:\Users\abhik\Desktop\chicken-disease-mlops\cnnClassifier\pipeline\stage_01_data_ingestion.py", line 16, in main
    data_ingestion = DataIngestion(config=data_ingestion_config)
  File "C:\Users\abhik\Desktop\chicken-disease-mlops\cnnClassifier\components\data_ingestion.py", line 12, in __init__
    print(self.config())
TypeError: DataIngestionConfig.__init__() missing 4 required positional arguments: 'root_dir', 'source_url', 'local_file_path', and 'unzip_dir'
[2024-03-02 22:57:32,474: INFO: main: >>>>>> stage Data Ingestion stage started <<<<<<]
[2024-03-02 22:57:32,480: INFO: common: yaml file: config\config.yaml loaded successfully]
[2024-03-02 22:57:32,482: INFO: common: yaml file: params.yaml loaded successfully]
[2024-03-02 22:57:32,483: INFO: common: created directory at: artifacts]
[2024-03-02 22:57:32,485: INFO: common: created directory at: artifacts/data_ingestion]
[2024-03-02 22:57:36,579: INFO: data_ingestion: artifacts/data_ingestion/data.zip download! with following info: 
Connection: close
Content-Length: 11616915
Cache-Control: max-age=300
Content-Security-Policy: default-src 'none'; style-src 'unsafe-inline'; sandbox
Content-Type: application/zip
ETag: "adf745abc03891fe493c3be264ec012691fe3fa21d861f35a27edbe6d86a76b1"
Strict-Transport-Security: max-age=31536000
X-Content-Type-Options: nosniff
X-Frame-Options: deny
X-XSS-Protection: 1; mode=block
X-GitHub-Request-Id: CCE8:1E6B17:147C05:1AD8A1:65E36183
Accept-Ranges: bytes
Date: Sat, 02 Mar 2024 17:27:34 GMT
Via: 1.1 varnish
X-Served-By: cache-hyd1100031-HYD
X-Cache: MISS
X-Cache-Hits: 0
X-Timer: S1709400453.432394,VS0,VE948
Vary: Authorization,Accept-Encoding,Origin
Access-Control-Allow-Origin: *
Cross-Origin-Resource-Policy: cross-origin
X-Fastly-Request-ID: 0b0b553dfcac55fa0f64a2aec450d71a98848ec0
Expires: Sat, 02 Mar 2024 17:32:34 GMT
Source-Age: 1

]
[2024-03-02 22:57:37,466: INFO: main: >>>>>> stage Data Ingestion stage completed <<<<<<

x==========x]
[2024-03-02 22:58:18,760: INFO: main: >>>>>> stage Data Ingestion stage started <<<<<<]
[2024-03-02 22:58:18,762: INFO: common: yaml file: config\config.yaml loaded successfully]
[2024-03-02 22:58:18,764: INFO: common: yaml file: params.yaml loaded successfully]
[2024-03-02 22:58:18,765: INFO: common: created directory at: artifacts]
[2024-03-02 22:58:18,766: INFO: common: created directory at: artifacts/data_ingestion]
[2024-03-02 22:58:18,768: ERROR: main: 'DataIngestionConfig' object has no attribute 'local_data_file']
Traceback (most recent call last):
  File "C:\Users\abhik\Desktop\chicken-disease-mlops\main.py", line 10, in <module>
    data_ingestion.main()
  File "C:\Users\abhik\Desktop\chicken-disease-mlops\cnnClassifier\pipeline\stage_01_data_ingestion.py", line 17, in main
    data_ingestion.download_file()
  File "C:\Users\abhik\Desktop\chicken-disease-mlops\cnnClassifier\components\data_ingestion.py", line 24, in download_file
    logger.info(f"File already exists of size: {get_size(Path(self.config.local_data_file))}")
AttributeError: 'DataIngestionConfig' object has no attribute 'local_data_file'
[2024-03-02 22:59:10,430: INFO: main: >>>>>> stage Data Ingestion stage started <<<<<<]
[2024-03-02 22:59:10,434: INFO: common: yaml file: config\config.yaml loaded successfully]
[2024-03-02 22:59:10,437: INFO: common: yaml file: params.yaml loaded successfully]
[2024-03-02 22:59:10,438: INFO: common: created directory at: artifacts]
[2024-03-02 22:59:10,440: INFO: common: created directory at: artifacts/data_ingestion]
[2024-03-02 22:59:10,441: ERROR: main: 'DataIngestionConfig' object has no attribute 'local_data_file']
Traceback (most recent call last):
  File "C:\Users\abhik\Desktop\chicken-disease-mlops\main.py", line 10, in <module>
    data_ingestion.main()
  File "C:\Users\abhik\Desktop\chicken-disease-mlops\cnnClassifier\pipeline\stage_01_data_ingestion.py", line 17, in main
    data_ingestion.download_file()
  File "C:\Users\abhik\Desktop\chicken-disease-mlops\cnnClassifier\components\data_ingestion.py", line 21, in download_file
    logger.info(f"File already exists of size: {get_size(Path(self.config.local_data_file))}")
AttributeError: 'DataIngestionConfig' object has no attribute 'local_data_file'
[2024-03-02 22:59:29,888: INFO: main: >>>>>> stage Data Ingestion stage started <<<<<<]
[2024-03-02 22:59:29,900: INFO: common: yaml file: config\config.yaml loaded successfully]
[2024-03-02 22:59:29,904: INFO: common: yaml file: params.yaml loaded successfully]
[2024-03-02 22:59:29,907: INFO: common: created directory at: artifacts]
[2024-03-02 22:59:29,909: INFO: common: created directory at: artifacts/data_ingestion]
[2024-03-02 22:59:32,818: INFO: data_ingestion: artifacts/data_ingestion/data.zip download! with following info: 
Connection: close
Content-Length: 11616915
Cache-Control: max-age=300
Content-Security-Policy: default-src 'none'; style-src 'unsafe-inline'; sandbox
Content-Type: application/zip
ETag: "adf745abc03891fe493c3be264ec012691fe3fa21d861f35a27edbe6d86a76b1"
Strict-Transport-Security: max-age=31536000
X-Content-Type-Options: nosniff
X-Frame-Options: deny
X-XSS-Protection: 1; mode=block
X-GitHub-Request-Id: CCE8:1E6B17:147C05:1AD8A1:65E36183
Accept-Ranges: bytes
Date: Sat, 02 Mar 2024 17:29:30 GMT
Via: 1.1 varnish
X-Served-By: cache-hyd1100022-HYD
X-Cache: HIT
X-Cache-Hits: 0
X-Timer: S1709400571.587605,VS0,VE1
Vary: Authorization,Accept-Encoding,Origin
Access-Control-Allow-Origin: *
Cross-Origin-Resource-Policy: cross-origin
X-Fastly-Request-ID: 56974edbd119ddeb13ffe4062b5def0650e3a7d2
Expires: Sat, 02 Mar 2024 17:34:30 GMT
Source-Age: 117

]
[2024-03-02 22:59:33,722: INFO: main: >>>>>> stage Data Ingestion stage completed <<<<<<

x==========x]
[2024-03-02 22:59:49,386: INFO: main: >>>>>> stage Data Ingestion stage started <<<<<<]
[2024-03-02 22:59:49,389: INFO: common: yaml file: config\config.yaml loaded successfully]
[2024-03-02 22:59:49,393: INFO: common: yaml file: params.yaml loaded successfully]
[2024-03-02 22:59:49,394: INFO: common: created directory at: artifacts]
[2024-03-02 22:59:49,396: INFO: common: created directory at: artifacts/data_ingestion]
[2024-03-02 22:59:49,397: ERROR: main: 'DataIngestionConfig' object has no attribute 'local_data_file']
Traceback (most recent call last):
  File "C:\Users\abhik\Desktop\chicken-disease-mlops\main.py", line 10, in <module>
    data_ingestion.main()
  File "C:\Users\abhik\Desktop\chicken-disease-mlops\cnnClassifier\pipeline\stage_01_data_ingestion.py", line 17, in main
    data_ingestion.download_file()
  File "C:\Users\abhik\Desktop\chicken-disease-mlops\cnnClassifier\components\data_ingestion.py", line 21, in download_file
    logger.info(f"File already exists of size: {get_size(Path(self.config.local_data_file))}")
AttributeError: 'DataIngestionConfig' object has no attribute 'local_data_file'
[2024-03-03 13:20:20,660: WARNING: module_wrapper: From C:\Users\abhik\Desktop\chicken-disease-mlops\venv\lib\site-packages\keras\src\losses.py:2976: The name tf.losses.sparse_softmax_cross_entropy is deprecated. Please use tf.compat.v1.losses.sparse_softmax_cross_entropy instead.
]
[2024-03-03 13:22:05,273: WARNING: module_wrapper: From C:\Users\abhik\Desktop\chicken-disease-mlops\venv\lib\site-packages\keras\src\losses.py:2976: The name tf.losses.sparse_softmax_cross_entropy is deprecated. Please use tf.compat.v1.losses.sparse_softmax_cross_entropy instead.
]
[2024-03-03 13:22:05,978: ERROR: main: [WinError 5] Access is denied: 'artifacts']
Traceback (most recent call last):
  File "C:\Users\abhik\Desktop\chicken-disease-mlops\main.py", line 9, in <module>
    os.remove('artifacts')
PermissionError: [WinError 5] Access is denied: 'artifacts'
[2024-03-03 13:22:54,191: WARNING: module_wrapper: From C:\Users\abhik\Desktop\chicken-disease-mlops\venv\lib\site-packages\keras\src\losses.py:2976: The name tf.losses.sparse_softmax_cross_entropy is deprecated. Please use tf.compat.v1.losses.sparse_softmax_cross_entropy instead.
]
[2024-03-03 13:22:54,895: INFO: main: >>>>>> stage Data Ingestion stage started <<<<<<]
[2024-03-03 13:22:54,895: INFO: common: yaml file: config\config.yaml loaded successfully]
[2024-03-03 13:22:54,918: INFO: common: yaml file: params.yaml loaded successfully]
[2024-03-03 13:22:54,920: INFO: common: created directory at: artifacts]
[2024-03-03 13:22:54,921: INFO: common: created directory at: artifacts/data_ingestion]
[2024-03-03 13:22:59,033: INFO: data_ingestion: artifacts/data_ingestion/data.zip download! with following info: 
Connection: close
Content-Length: 11616915
Cache-Control: max-age=300
Content-Security-Policy: default-src 'none'; style-src 'unsafe-inline'; sandbox
Content-Type: application/zip
ETag: "adf745abc03891fe493c3be264ec012691fe3fa21d861f35a27edbe6d86a76b1"
Strict-Transport-Security: max-age=31536000
X-Content-Type-Options: nosniff
X-Frame-Options: deny
X-XSS-Protection: 1; mode=block
X-GitHub-Request-Id: 145E:15F2FC:290DD1:365EF8:65E42C57
Accept-Ranges: bytes
Date: Sun, 03 Mar 2024 07:52:57 GMT
Via: 1.1 varnish
X-Served-By: cache-hyd1100033-HYD
X-Cache: MISS
X-Cache-Hits: 0
X-Timer: S1709452376.281833,VS0,VE929
Vary: Authorization,Accept-Encoding,Origin
Access-Control-Allow-Origin: *
Cross-Origin-Resource-Policy: cross-origin
X-Fastly-Request-ID: 9fb65d0b12f9d39c660c66921d54e119b469c70a
Expires: Sun, 03 Mar 2024 07:57:57 GMT
Source-Age: 1

]
[2024-03-03 13:22:59,550: INFO: main: >>>>>> stage Data Ingestion stage completed <<<<<<

x==========x]
[2024-03-03 13:22:59,550: INFO: main: >>>>>>>>STAGE PrePare Base Model started<<<<<<<<<<<<<]
[2024-03-03 13:22:59,550: INFO: common: yaml file: config\config.yaml loaded successfully]
[2024-03-03 13:22:59,564: INFO: common: yaml file: params.yaml loaded successfully]
[2024-03-03 13:22:59,566: INFO: common: created directory at: artifacts]
[2024-03-03 13:22:59,566: INFO: common: created directory at: artifacts/prepare_base_model]
[2024-03-03 13:22:59,566: ERROR: main: module 'keras.api._v2.keras' has no attribute 'application']
Traceback (most recent call last):
  File "C:\Users\abhik\Desktop\chicken-disease-mlops\main.py", line 23, in <module>
    prepare_base_model.main()
  File "C:\Users\abhik\Desktop\chicken-disease-mlops\cnnClassifier\pipeline\stage_02_prepare_base_model.py", line 16, in main
    prepare_base_model.get_base_model()
  File "C:\Users\abhik\Desktop\chicken-disease-mlops\cnnClassifier\components\prepare_base_model.py", line 15, in get_base_model
    self.model = tf.keras.application.vgg16.VGG16(
AttributeError: module 'keras.api._v2.keras' has no attribute 'application'
[2024-03-03 13:23:18,945: WARNING: module_wrapper: From C:\Users\abhik\Desktop\chicken-disease-mlops\venv\lib\site-packages\keras\src\losses.py:2976: The name tf.losses.sparse_softmax_cross_entropy is deprecated. Please use tf.compat.v1.losses.sparse_softmax_cross_entropy instead.
]
[2024-03-03 13:23:19,580: INFO: main: >>>>>> stage Data Ingestion stage started <<<<<<]
[2024-03-03 13:23:19,580: INFO: common: yaml file: config\config.yaml loaded successfully]
[2024-03-03 13:23:19,580: INFO: common: yaml file: params.yaml loaded successfully]
[2024-03-03 13:23:19,580: INFO: common: created directory at: artifacts]
[2024-03-03 13:23:19,580: INFO: common: created directory at: artifacts/data_ingestion]
[2024-03-03 13:23:22,250: INFO: data_ingestion: artifacts/data_ingestion/data.zip download! with following info: 
Connection: close
Content-Length: 11616915
Cache-Control: max-age=300
Content-Security-Policy: default-src 'none'; style-src 'unsafe-inline'; sandbox
Content-Type: application/zip
ETag: "adf745abc03891fe493c3be264ec012691fe3fa21d861f35a27edbe6d86a76b1"
Strict-Transport-Security: max-age=31536000
X-Content-Type-Options: nosniff
X-Frame-Options: deny
X-XSS-Protection: 1; mode=block
X-GitHub-Request-Id: 145E:15F2FC:290DD1:365EF8:65E42C57
Accept-Ranges: bytes
Date: Sun, 03 Mar 2024 07:53:20 GMT
Via: 1.1 varnish
X-Served-By: cache-hyd1100025-HYD
X-Cache: HIT
X-Cache-Hits: 0
X-Timer: S1709452401.616886,VS0,VE1
Vary: Authorization,Accept-Encoding,Origin
Access-Control-Allow-Origin: *
Cross-Origin-Resource-Policy: cross-origin
X-Fastly-Request-ID: 0064acd0a398447800e1d65b2e0f382e5540c620
Expires: Sun, 03 Mar 2024 07:58:20 GMT
Source-Age: 24

]
[2024-03-03 13:23:22,689: INFO: main: >>>>>> stage Data Ingestion stage completed <<<<<<

x==========x]
[2024-03-03 13:23:22,689: INFO: main: >>>>>>>>STAGE PrePare Base Model started<<<<<<<<<<<<<]
[2024-03-03 13:23:22,689: INFO: common: yaml file: config\config.yaml loaded successfully]
[2024-03-03 13:23:22,704: INFO: common: yaml file: params.yaml loaded successfully]
[2024-03-03 13:23:22,704: INFO: common: created directory at: artifacts]
[2024-03-03 13:23:22,704: INFO: common: created directory at: artifacts/prepare_base_model]
[2024-03-03 13:23:22,974: WARNING: module_wrapper: From C:\Users\abhik\Desktop\chicken-disease-mlops\venv\lib\site-packages\keras\src\backend.py:1398: The name tf.executing_eagerly_outside_functions is deprecated. Please use tf.compat.v1.executing_eagerly_outside_functions instead.
]
[2024-03-03 13:23:23,150: WARNING: module_wrapper: From C:\Users\abhik\Desktop\chicken-disease-mlops\venv\lib\site-packages\keras\src\layers\pooling\max_pooling2d.py:161: The name tf.nn.max_pool is deprecated. Please use tf.nn.max_pool2d instead.
]
[2024-03-03 13:23:37,965: WARNING: saving_utils: Compiled the loaded model, but the compiled metrics have yet to be built. `model.compile_metrics` will be empty until you train or evaluate the model.]
[2024-03-03 13:23:38,181: ERROR: main: Dense.__init__() missing 1 required positional argument: 'units']
Traceback (most recent call last):
  File "C:\Users\abhik\Desktop\chicken-disease-mlops\main.py", line 23, in <module>
    prepare_base_model.main()
  File "C:\Users\abhik\Desktop\chicken-disease-mlops\cnnClassifier\pipeline\stage_02_prepare_base_model.py", line 17, in main
    prepare_base_model.update_base_model()
  File "C:\Users\abhik\Desktop\chicken-disease-mlops\cnnClassifier\components\prepare_base_model.py", line 56, in update_base_model
    self.full_model = self._prepare_full_model(
  File "C:\Users\abhik\Desktop\chicken-disease-mlops\cnnClassifier\components\prepare_base_model.py", line 36, in _prepare_full_model
    prediction = tf.keras.layers.Dense(
  File "C:\Users\abhik\Desktop\chicken-disease-mlops\venv\lib\site-packages\keras\src\dtensor\utils.py", line 96, in _wrap_function
    init_method(layer_instance, *args, **kwargs)
TypeError: Dense.__init__() missing 1 required positional argument: 'units'
[2024-03-03 13:26:48,502: WARNING: module_wrapper: From C:\Users\abhik\Desktop\chicken-disease-mlops\venv\lib\site-packages\keras\src\losses.py:2976: The name tf.losses.sparse_softmax_cross_entropy is deprecated. Please use tf.compat.v1.losses.sparse_softmax_cross_entropy instead.
]
[2024-03-03 13:26:49,127: INFO: main: >>>>>> stage Data Ingestion stage started <<<<<<]
[2024-03-03 13:26:49,127: INFO: common: yaml file: config\config.yaml loaded successfully]
[2024-03-03 13:26:49,144: INFO: common: yaml file: params.yaml loaded successfully]
[2024-03-03 13:26:49,145: INFO: common: created directory at: artifacts]
[2024-03-03 13:26:49,146: INFO: common: created directory at: artifacts/data_ingestion]
[2024-03-03 13:26:51,843: INFO: data_ingestion: artifacts/data_ingestion/data.zip download! with following info: 
Connection: close
Content-Length: 11616915
Cache-Control: max-age=300
Content-Security-Policy: default-src 'none'; style-src 'unsafe-inline'; sandbox
Content-Type: application/zip
ETag: "adf745abc03891fe493c3be264ec012691fe3fa21d861f35a27edbe6d86a76b1"
Strict-Transport-Security: max-age=31536000
X-Content-Type-Options: nosniff
X-Frame-Options: deny
X-XSS-Protection: 1; mode=block
X-GitHub-Request-Id: 145E:15F2FC:290DD1:365EF8:65E42C57
Accept-Ranges: bytes
Date: Sun, 03 Mar 2024 07:56:50 GMT
Via: 1.1 varnish
X-Served-By: cache-hyd1100026-HYD
X-Cache: HIT
X-Cache-Hits: 0
X-Timer: S1709452610.431591,VS0,VE1
Vary: Authorization,Accept-Encoding,Origin
Access-Control-Allow-Origin: *
Cross-Origin-Resource-Policy: cross-origin
X-Fastly-Request-ID: 88e5934e1269c7f2b966c034ce09963495f466dc
Expires: Sun, 03 Mar 2024 08:01:50 GMT
Source-Age: 234

]
[2024-03-03 13:26:52,311: INFO: main: >>>>>> stage Data Ingestion stage completed <<<<<<

x==========x]
[2024-03-03 13:26:52,311: INFO: main: >>>>>>>>STAGE PrePare Base Model started<<<<<<<<<<<<<]
[2024-03-03 13:26:52,311: INFO: common: yaml file: config\config.yaml loaded successfully]
[2024-03-03 13:26:52,311: INFO: common: yaml file: params.yaml loaded successfully]
[2024-03-03 13:26:52,311: INFO: common: created directory at: artifacts]
[2024-03-03 13:26:52,311: INFO: common: created directory at: artifacts/prepare_base_model]
[2024-03-03 13:26:52,549: WARNING: module_wrapper: From C:\Users\abhik\Desktop\chicken-disease-mlops\venv\lib\site-packages\keras\src\backend.py:1398: The name tf.executing_eagerly_outside_functions is deprecated. Please use tf.compat.v1.executing_eagerly_outside_functions instead.
]
[2024-03-03 13:26:52,645: WARNING: module_wrapper: From C:\Users\abhik\Desktop\chicken-disease-mlops\venv\lib\site-packages\keras\src\layers\pooling\max_pooling2d.py:161: The name tf.nn.max_pool is deprecated. Please use tf.nn.max_pool2d instead.
]
[2024-03-03 13:26:53,111: WARNING: saving_utils: Compiled the loaded model, but the compiled metrics have yet to be built. `model.compile_metrics` will be empty until you train or evaluate the model.]
[2024-03-03 13:26:53,272: ERROR: main: Unknown activation function 'softwax' cannot be deserialized.]
Traceback (most recent call last):
  File "C:\Users\abhik\Desktop\chicken-disease-mlops\main.py", line 23, in <module>
    prepare_base_model.main()
  File "C:\Users\abhik\Desktop\chicken-disease-mlops\cnnClassifier\pipeline\stage_02_prepare_base_model.py", line 17, in main
    prepare_base_model.update_base_model()
  File "C:\Users\abhik\Desktop\chicken-disease-mlops\cnnClassifier\components\prepare_base_model.py", line 56, in update_base_model
    self.full_model = self._prepare_full_model(
  File "C:\Users\abhik\Desktop\chicken-disease-mlops\cnnClassifier\components\prepare_base_model.py", line 36, in _prepare_full_model
    prediction = tf.keras.layers.Dense(
  File "C:\Users\abhik\Desktop\chicken-disease-mlops\venv\lib\site-packages\keras\src\dtensor\utils.py", line 96, in _wrap_function
    init_method(layer_instance, *args, **kwargs)
  File "C:\Users\abhik\Desktop\chicken-disease-mlops\venv\lib\site-packages\keras\src\layers\core\dense.py", line 125, in __init__
    self.activation = activations.get(activation)
  File "C:\Users\abhik\Desktop\chicken-disease-mlops\venv\lib\site-packages\tensorflow\python\util\traceback_utils.py", line 153, in error_handler
    raise e.with_traceback(filtered_tb) from None
  File "C:\Users\abhik\Desktop\chicken-disease-mlops\venv\lib\site-packages\keras\src\activations.py", line 691, in get
    return deserialize(identifier, use_legacy_format=use_legacy_format)
  File "C:\Users\abhik\Desktop\chicken-disease-mlops\venv\lib\site-packages\keras\src\activations.py", line 646, in deserialize
    raise ValueError(
ValueError: Unknown activation function 'softwax' cannot be deserialized.
[2024-03-03 13:27:11,181: WARNING: module_wrapper: From C:\Users\abhik\Desktop\chicken-disease-mlops\venv\lib\site-packages\keras\src\losses.py:2976: The name tf.losses.sparse_softmax_cross_entropy is deprecated. Please use tf.compat.v1.losses.sparse_softmax_cross_entropy instead.
]
[2024-03-03 13:27:11,806: INFO: main: >>>>>> stage Data Ingestion stage started <<<<<<]
[2024-03-03 13:27:11,806: INFO: common: yaml file: config\config.yaml loaded successfully]
[2024-03-03 13:27:11,806: INFO: common: yaml file: params.yaml loaded successfully]
[2024-03-03 13:27:11,806: INFO: common: created directory at: artifacts]
[2024-03-03 13:27:11,806: INFO: common: created directory at: artifacts/data_ingestion]
[2024-03-03 13:27:14,462: INFO: data_ingestion: artifacts/data_ingestion/data.zip download! with following info: 
Connection: close
Content-Length: 11616915
Cache-Control: max-age=300
Content-Security-Policy: default-src 'none'; style-src 'unsafe-inline'; sandbox
Content-Type: application/zip
ETag: "adf745abc03891fe493c3be264ec012691fe3fa21d861f35a27edbe6d86a76b1"
Strict-Transport-Security: max-age=31536000
X-Content-Type-Options: nosniff
X-Frame-Options: deny
X-XSS-Protection: 1; mode=block
X-GitHub-Request-Id: 145E:15F2FC:290DD1:365EF8:65E42C57
Accept-Ranges: bytes
Date: Sun, 03 Mar 2024 07:57:12 GMT
Via: 1.1 varnish
X-Served-By: cache-hyd1100022-HYD
X-Cache: HIT
X-Cache-Hits: 0
X-Timer: S1709452633.881399,VS0,VE1
Vary: Authorization,Accept-Encoding,Origin
Access-Control-Allow-Origin: *
Cross-Origin-Resource-Policy: cross-origin
X-Fastly-Request-ID: 31ae022ca29f27c90a9770307cad95bf8675dca9
Expires: Sun, 03 Mar 2024 08:02:12 GMT
Source-Age: 256

]
[2024-03-03 13:27:14,884: INFO: main: >>>>>> stage Data Ingestion stage completed <<<<<<

x==========x]
[2024-03-03 13:27:14,884: INFO: main: >>>>>>>>STAGE PrePare Base Model started<<<<<<<<<<<<<]
[2024-03-03 13:27:14,884: INFO: common: yaml file: config\config.yaml loaded successfully]
[2024-03-03 13:27:14,884: INFO: common: yaml file: params.yaml loaded successfully]
[2024-03-03 13:27:14,884: INFO: common: created directory at: artifacts]
[2024-03-03 13:27:14,899: INFO: common: created directory at: artifacts/prepare_base_model]
[2024-03-03 13:27:15,114: WARNING: module_wrapper: From C:\Users\abhik\Desktop\chicken-disease-mlops\venv\lib\site-packages\keras\src\backend.py:1398: The name tf.executing_eagerly_outside_functions is deprecated. Please use tf.compat.v1.executing_eagerly_outside_functions instead.
]
[2024-03-03 13:27:15,213: WARNING: module_wrapper: From C:\Users\abhik\Desktop\chicken-disease-mlops\venv\lib\site-packages\keras\src\layers\pooling\max_pooling2d.py:161: The name tf.nn.max_pool is deprecated. Please use tf.nn.max_pool2d instead.
]
[2024-03-03 13:27:15,700: WARNING: saving_utils: Compiled the loaded model, but the compiled metrics have yet to be built. `model.compile_metrics` will be empty until you train or evaluate the model.]
[2024-03-03 13:27:15,833: ERROR: main: module 'keras.api._v2.keras.models' has no attribute 'model']
Traceback (most recent call last):
  File "C:\Users\abhik\Desktop\chicken-disease-mlops\main.py", line 23, in <module>
    prepare_base_model.main()
  File "C:\Users\abhik\Desktop\chicken-disease-mlops\cnnClassifier\pipeline\stage_02_prepare_base_model.py", line 17, in main
    prepare_base_model.update_base_model()
  File "C:\Users\abhik\Desktop\chicken-disease-mlops\cnnClassifier\components\prepare_base_model.py", line 56, in update_base_model
    self.full_model = self._prepare_full_model(
  File "C:\Users\abhik\Desktop\chicken-disease-mlops\cnnClassifier\components\prepare_base_model.py", line 41, in _prepare_full_model
    full_model = tf.keras.models.model(
AttributeError: module 'keras.api._v2.keras.models' has no attribute 'model'
[2024-03-03 13:27:54,529: WARNING: module_wrapper: From C:\Users\abhik\Desktop\chicken-disease-mlops\venv\lib\site-packages\keras\src\losses.py:2976: The name tf.losses.sparse_softmax_cross_entropy is deprecated. Please use tf.compat.v1.losses.sparse_softmax_cross_entropy instead.
]
[2024-03-03 13:27:55,152: INFO: main: >>>>>> stage Data Ingestion stage started <<<<<<]
[2024-03-03 13:27:55,152: INFO: common: yaml file: config\config.yaml loaded successfully]
[2024-03-03 13:27:55,152: INFO: common: yaml file: params.yaml loaded successfully]
[2024-03-03 13:27:55,152: INFO: common: created directory at: artifacts]
[2024-03-03 13:27:55,152: INFO: common: created directory at: artifacts/data_ingestion]
[2024-03-03 13:27:57,912: INFO: data_ingestion: artifacts/data_ingestion/data.zip download! with following info: 
Connection: close
Content-Length: 11616915
Cache-Control: max-age=300
Content-Security-Policy: default-src 'none'; style-src 'unsafe-inline'; sandbox
Content-Type: application/zip
ETag: "adf745abc03891fe493c3be264ec012691fe3fa21d861f35a27edbe6d86a76b1"
Strict-Transport-Security: max-age=31536000
X-Content-Type-Options: nosniff
X-Frame-Options: deny
X-XSS-Protection: 1; mode=block
X-GitHub-Request-Id: 145E:15F2FC:290DD1:365EF8:65E42C57
Accept-Ranges: bytes
Date: Sun, 03 Mar 2024 07:57:56 GMT
Via: 1.1 varnish
X-Served-By: cache-hyd1100029-HYD
X-Cache: HIT
X-Cache-Hits: 0
X-Timer: S1709452676.192573,VS0,VE1
Vary: Authorization,Accept-Encoding,Origin
Access-Control-Allow-Origin: *
Cross-Origin-Resource-Policy: cross-origin
X-Fastly-Request-ID: 99e00ebeedf0419730650fd5ce1af3038e44d0bc
Expires: Sun, 03 Mar 2024 08:02:56 GMT
Source-Age: 300

]
[2024-03-03 13:27:58,351: INFO: main: >>>>>> stage Data Ingestion stage completed <<<<<<

x==========x]
[2024-03-03 13:27:58,351: INFO: main: >>>>>>>>STAGE PrePare Base Model started<<<<<<<<<<<<<]
[2024-03-03 13:27:58,351: INFO: common: yaml file: config\config.yaml loaded successfully]
[2024-03-03 13:27:58,351: INFO: common: yaml file: params.yaml loaded successfully]
[2024-03-03 13:27:58,351: INFO: common: created directory at: artifacts]
[2024-03-03 13:27:58,367: INFO: common: created directory at: artifacts/prepare_base_model]
[2024-03-03 13:27:58,587: WARNING: module_wrapper: From C:\Users\abhik\Desktop\chicken-disease-mlops\venv\lib\site-packages\keras\src\backend.py:1398: The name tf.executing_eagerly_outside_functions is deprecated. Please use tf.compat.v1.executing_eagerly_outside_functions instead.
]
[2024-03-03 13:27:58,683: WARNING: module_wrapper: From C:\Users\abhik\Desktop\chicken-disease-mlops\venv\lib\site-packages\keras\src\layers\pooling\max_pooling2d.py:161: The name tf.nn.max_pool is deprecated. Please use tf.nn.max_pool2d instead.
]
[2024-03-03 13:27:59,138: WARNING: saving_utils: Compiled the loaded model, but the compiled metrics have yet to be built. `model.compile_metrics` will be empty until you train or evaluate the model.]
[2024-03-03 13:27:59,324: ERROR: main: module 'keras.api._v2.keras' has no attribute 'Models']
Traceback (most recent call last):
  File "C:\Users\abhik\Desktop\chicken-disease-mlops\main.py", line 23, in <module>
    prepare_base_model.main()
  File "C:\Users\abhik\Desktop\chicken-disease-mlops\cnnClassifier\pipeline\stage_02_prepare_base_model.py", line 17, in main
    prepare_base_model.update_base_model()
  File "C:\Users\abhik\Desktop\chicken-disease-mlops\cnnClassifier\components\prepare_base_model.py", line 56, in update_base_model
    self.full_model = self._prepare_full_model(
  File "C:\Users\abhik\Desktop\chicken-disease-mlops\cnnClassifier\components\prepare_base_model.py", line 41, in _prepare_full_model
    full_model = tf.keras.Models.Model(
AttributeError: module 'keras.api._v2.keras' has no attribute 'Models'
[2024-03-03 13:28:15,805: WARNING: module_wrapper: From C:\Users\abhik\Desktop\chicken-disease-mlops\venv\lib\site-packages\keras\src\losses.py:2976: The name tf.losses.sparse_softmax_cross_entropy is deprecated. Please use tf.compat.v1.losses.sparse_softmax_cross_entropy instead.
]
[2024-03-03 13:28:16,435: INFO: main: >>>>>> stage Data Ingestion stage started <<<<<<]
[2024-03-03 13:28:16,450: INFO: common: yaml file: config\config.yaml loaded successfully]
[2024-03-03 13:28:16,450: INFO: common: yaml file: params.yaml loaded successfully]
[2024-03-03 13:28:16,450: INFO: common: created directory at: artifacts]
[2024-03-03 13:28:16,450: INFO: common: created directory at: artifacts/data_ingestion]
[2024-03-03 13:28:19,518: INFO: data_ingestion: artifacts/data_ingestion/data.zip download! with following info: 
Connection: close
Content-Length: 11616915
Cache-Control: max-age=300
Content-Security-Policy: default-src 'none'; style-src 'unsafe-inline'; sandbox
Content-Type: application/zip
ETag: "adf745abc03891fe493c3be264ec012691fe3fa21d861f35a27edbe6d86a76b1"
Strict-Transport-Security: max-age=31536000
X-Content-Type-Options: nosniff
X-Frame-Options: deny
X-XSS-Protection: 1; mode=block
X-GitHub-Request-Id: 145E:15F2FC:290DD1:365EF8:65E42C57
Accept-Ranges: bytes
Date: Sun, 03 Mar 2024 07:58:17 GMT
Via: 1.1 varnish
X-Served-By: cache-hyd1100032-HYD
X-Cache: HIT
X-Cache-Hits: 0
X-Timer: S1709452698.502971,VS0,VE276
Vary: Authorization,Accept-Encoding,Origin
Access-Control-Allow-Origin: *
Cross-Origin-Resource-Policy: cross-origin
X-Fastly-Request-ID: f1f48e820e431aa849fd419a79ad032ce30079f3
Expires: Sun, 03 Mar 2024 08:03:17 GMT
Source-Age: 0

]
[2024-03-03 13:28:19,960: INFO: main: >>>>>> stage Data Ingestion stage completed <<<<<<

x==========x]
[2024-03-03 13:28:19,960: INFO: main: >>>>>>>>STAGE PrePare Base Model started<<<<<<<<<<<<<]
[2024-03-03 13:28:19,960: INFO: common: yaml file: config\config.yaml loaded successfully]
[2024-03-03 13:28:19,960: INFO: common: yaml file: params.yaml loaded successfully]
[2024-03-03 13:28:19,960: INFO: common: created directory at: artifacts]
[2024-03-03 13:28:19,969: INFO: common: created directory at: artifacts/prepare_base_model]
[2024-03-03 13:28:20,186: WARNING: module_wrapper: From C:\Users\abhik\Desktop\chicken-disease-mlops\venv\lib\site-packages\keras\src\backend.py:1398: The name tf.executing_eagerly_outside_functions is deprecated. Please use tf.compat.v1.executing_eagerly_outside_functions instead.
]
[2024-03-03 13:28:20,291: WARNING: module_wrapper: From C:\Users\abhik\Desktop\chicken-disease-mlops\venv\lib\site-packages\keras\src\layers\pooling\max_pooling2d.py:161: The name tf.nn.max_pool is deprecated. Please use tf.nn.max_pool2d instead.
]
[2024-03-03 13:28:20,794: WARNING: saving_utils: Compiled the loaded model, but the compiled metrics have yet to be built. `model.compile_metrics` will be empty until you train or evaluate the model.]
[2024-03-03 13:28:21,000: ERROR: main: ('Keyword argument not understood:', 'input')]
Traceback (most recent call last):
  File "C:\Users\abhik\Desktop\chicken-disease-mlops\main.py", line 23, in <module>
    prepare_base_model.main()
  File "C:\Users\abhik\Desktop\chicken-disease-mlops\cnnClassifier\pipeline\stage_02_prepare_base_model.py", line 17, in main
    prepare_base_model.update_base_model()
  File "C:\Users\abhik\Desktop\chicken-disease-mlops\cnnClassifier\components\prepare_base_model.py", line 56, in update_base_model
    self.full_model = self._prepare_full_model(
  File "C:\Users\abhik\Desktop\chicken-disease-mlops\cnnClassifier\components\prepare_base_model.py", line 41, in _prepare_full_model
    full_model = tf.keras.models.Model(
  File "C:\Users\abhik\Desktop\chicken-disease-mlops\venv\lib\site-packages\tensorflow\python\trackable\base.py", line 204, in _method_wrapper
    result = method(self, *args, **kwargs)
  File "C:\Users\abhik\Desktop\chicken-disease-mlops\venv\lib\site-packages\keras\src\utils\traceback_utils.py", line 70, in error_handler
    raise e.with_traceback(filtered_tb) from None
  File "C:\Users\abhik\Desktop\chicken-disease-mlops\venv\lib\site-packages\keras\src\utils\generic_utils.py", line 514, in validate_kwargs
    raise TypeError(error_message, kwarg)
TypeError: ('Keyword argument not understood:', 'input')
[2024-03-03 13:28:49,373: WARNING: module_wrapper: From C:\Users\abhik\Desktop\chicken-disease-mlops\venv\lib\site-packages\keras\src\losses.py:2976: The name tf.losses.sparse_softmax_cross_entropy is deprecated. Please use tf.compat.v1.losses.sparse_softmax_cross_entropy instead.
]
[2024-03-03 13:28:50,000: INFO: main: >>>>>> stage Data Ingestion stage started <<<<<<]
[2024-03-03 13:28:50,000: INFO: common: yaml file: config\config.yaml loaded successfully]
[2024-03-03 13:28:50,015: INFO: common: yaml file: params.yaml loaded successfully]
[2024-03-03 13:28:50,015: INFO: common: created directory at: artifacts]
[2024-03-03 13:28:50,015: INFO: common: created directory at: artifacts/data_ingestion]
[2024-03-03 13:28:52,653: INFO: data_ingestion: artifacts/data_ingestion/data.zip download! with following info: 
Connection: close
Content-Length: 11616915
Cache-Control: max-age=300
Content-Security-Policy: default-src 'none'; style-src 'unsafe-inline'; sandbox
Content-Type: application/zip
ETag: "adf745abc03891fe493c3be264ec012691fe3fa21d861f35a27edbe6d86a76b1"
Strict-Transport-Security: max-age=31536000
X-Content-Type-Options: nosniff
X-Frame-Options: deny
X-XSS-Protection: 1; mode=block
X-GitHub-Request-Id: 145E:15F2FC:290DD1:365EF8:65E42C57
Accept-Ranges: bytes
Date: Sun, 03 Mar 2024 07:58:51 GMT
Via: 1.1 varnish
X-Served-By: cache-hyd1100025-HYD
X-Cache: HIT
X-Cache-Hits: 0
X-Timer: S1709452731.033832,VS0,VE1
Vary: Authorization,Accept-Encoding,Origin
Access-Control-Allow-Origin: *
Cross-Origin-Resource-Policy: cross-origin
X-Fastly-Request-ID: 40506fb491c45f241f09f282ac3bb74b716d732e
Expires: Sun, 03 Mar 2024 08:03:51 GMT
Source-Age: 33

]
[2024-03-03 13:28:53,039: INFO: main: >>>>>> stage Data Ingestion stage completed <<<<<<

x==========x]
[2024-03-03 13:28:53,039: INFO: main: >>>>>>>>STAGE PrePare Base Model started<<<<<<<<<<<<<]
[2024-03-03 13:28:53,055: INFO: common: yaml file: config\config.yaml loaded successfully]
[2024-03-03 13:28:53,055: INFO: common: yaml file: params.yaml loaded successfully]
[2024-03-03 13:28:53,055: INFO: common: created directory at: artifacts]
[2024-03-03 13:28:53,055: INFO: common: created directory at: artifacts/prepare_base_model]
[2024-03-03 13:28:53,270: WARNING: module_wrapper: From C:\Users\abhik\Desktop\chicken-disease-mlops\venv\lib\site-packages\keras\src\backend.py:1398: The name tf.executing_eagerly_outside_functions is deprecated. Please use tf.compat.v1.executing_eagerly_outside_functions instead.
]
[2024-03-03 13:28:53,389: WARNING: module_wrapper: From C:\Users\abhik\Desktop\chicken-disease-mlops\venv\lib\site-packages\keras\src\layers\pooling\max_pooling2d.py:161: The name tf.nn.max_pool is deprecated. Please use tf.nn.max_pool2d instead.
]
[2024-03-03 13:28:53,844: WARNING: saving_utils: Compiled the loaded model, but the compiled metrics have yet to be built. `model.compile_metrics` will be empty until you train or evaluate the model.]
[2024-03-03 13:28:54,151: INFO: main: >>>stage PrePare Base Model completed<<<<<<]
